[2022-05-19 02:00:16,700] {taskinstance.py:1043} INFO - Dependencies all met for <TaskInstance: ETL.crear_tablas_en_postgres manual__2022-05-05T15:19:55.441542+00:00 [queued]>
[2022-05-19 02:00:17,071] {taskinstance.py:1043} INFO - Dependencies all met for <TaskInstance: ETL.crear_tablas_en_postgres manual__2022-05-05T15:19:55.441542+00:00 [queued]>
[2022-05-19 02:00:17,075] {taskinstance.py:1249} INFO - 
--------------------------------------------------------------------------------
[2022-05-19 02:00:17,182] {taskinstance.py:1250} INFO - Starting attempt 2 of 2
[2022-05-19 02:00:17,205] {taskinstance.py:1251} INFO - 
--------------------------------------------------------------------------------
[2022-05-19 02:00:17,525] {taskinstance.py:1270} INFO - Executing <Task(PostgresOperator): crear_tablas_en_postgres> on 2022-05-05 15:19:55.441542+00:00
[2022-05-19 02:00:17,936] {standard_task_runner.py:52} INFO - Started process 3087 to run task
[2022-05-19 02:00:17,978] {standard_task_runner.py:79} INFO - Running: ['***', 'tasks', 'run', 'ETL', 'crear_tablas_en_postgres', 'manual__2022-05-05T15:19:55.441542+00:00', '--job-id', '21', '--raw', '--subdir', 'DAGS_FOLDER/ELT.py', '--cfg-path', '/tmp/tmpwe73us13', '--error-file', '/tmp/tmpg0wvxijq']
[2022-05-19 02:00:18,035] {standard_task_runner.py:80} INFO - Job 21: Subtask crear_tablas_en_postgres
[2022-05-19 02:00:19,525] {logging_mixin.py:109} INFO - Running <TaskInstance: ETL.crear_tablas_en_postgres manual__2022-05-05T15:19:55.441542+00:00 [running]> on host 096c3bc3ad3a
[2022-05-19 02:00:20,465] {taskinstance.py:1448} INFO - Exporting the following env vars:
AIRFLOW_CTX_DAG_EMAIL=estudiante@uniandes.edu.co
AIRFLOW_CTX_DAG_OWNER=Estudiante
AIRFLOW_CTX_DAG_ID=ETL
AIRFLOW_CTX_TASK_ID=crear_tablas_en_postgres
AIRFLOW_CTX_EXECUTION_DATE=2022-05-05T15:19:55.441542+00:00
AIRFLOW_CTX_DAG_RUN_ID=manual__2022-05-05T15:19:55.441542+00:00
[2022-05-19 02:00:20,639] {base.py:79} INFO - Using connection to: id: postgres_localhost. Host: host.docker.internal, Port: 5432, Schema: WWWIDWGrupo16, Login: Grupo16BI, Password: ***, extra: {}
[2022-05-19 02:00:21,955] {taskinstance.py:1774} ERROR - Task failed with exception
Traceback (most recent call last):
  File "/home/airflow/.local/lib/python3.7/site-packages/airflow/providers/postgres/operators/postgres.py", line 92, in execute
    self.hook.run(self.sql, self.autocommit, parameters=self.parameters)
  File "/home/airflow/.local/lib/python3.7/site-packages/airflow/hooks/dbapi.py", line 198, in run
    with closing(self.get_conn()) as conn:
  File "/home/airflow/.local/lib/python3.7/site-packages/airflow/providers/postgres/hooks/postgres.py", line 113, in get_conn
    self.conn = psycopg2.connect(**conn_args)
  File "/home/airflow/.local/lib/python3.7/site-packages/psycopg2/__init__.py", line 122, in connect
    conn = _connect(dsn, connection_factory=connection_factory, **kwasync)
psycopg2.OperationalError
[2022-05-19 02:00:22,850] {taskinstance.py:1288} INFO - Marking task as FAILED. dag_id=ETL, task_id=crear_tablas_en_postgres, execution_date=20220505T151955, start_date=20220519T020016, end_date=20220519T020022
[2022-05-19 02:00:22,986] {standard_task_runner.py:98} ERROR - Failed to execute job 21 for task crear_tablas_en_postgres (; 3087)
[2022-05-19 02:00:23,385] {local_task_job.py:154} INFO - Task exited with return code 1
[2022-05-19 02:00:23,584] {local_task_job.py:264} INFO - 0 downstream tasks scheduled from follow-on schedule check
