[2022-05-19 02:00:40,327] {taskinstance.py:1043} INFO - Dependencies all met for <TaskInstance: ETL.poblar_tablas.poblar_date manual__2022-05-05T15:19:55.441542+00:00 [queued]>
[2022-05-19 02:00:40,735] {taskinstance.py:1043} INFO - Dependencies all met for <TaskInstance: ETL.poblar_tablas.poblar_date manual__2022-05-05T15:19:55.441542+00:00 [queued]>
[2022-05-19 02:00:40,754] {taskinstance.py:1249} INFO - 
--------------------------------------------------------------------------------
[2022-05-19 02:00:40,770] {taskinstance.py:1250} INFO - Starting attempt 1 of 1
[2022-05-19 02:00:40,773] {taskinstance.py:1251} INFO - 
--------------------------------------------------------------------------------
[2022-05-19 02:00:40,987] {taskinstance.py:1270} INFO - Executing <Task(PostgresOperator): poblar_tablas.poblar_date> on 2022-05-05 15:19:55.441542+00:00
[2022-05-19 02:00:41,023] {standard_task_runner.py:52} INFO - Started process 3099 to run task
[2022-05-19 02:00:41,141] {standard_task_runner.py:79} INFO - Running: ['***', 'tasks', 'run', 'ETL', 'poblar_tablas.poblar_date', 'manual__2022-05-05T15:19:55.441542+00:00', '--job-id', '24', '--raw', '--subdir', 'DAGS_FOLDER/ELT.py', '--cfg-path', '/tmp/tmpqw567ni1', '--error-file', '/tmp/tmpjwlep51q']
[2022-05-19 02:00:41,222] {standard_task_runner.py:80} INFO - Job 24: Subtask poblar_tablas.poblar_date
[2022-05-19 02:00:42,530] {logging_mixin.py:109} INFO - Running <TaskInstance: ETL.poblar_tablas.poblar_date manual__2022-05-05T15:19:55.441542+00:00 [running]> on host 096c3bc3ad3a
[2022-05-19 02:00:43,521] {taskinstance.py:1448} INFO - Exporting the following env vars:
AIRFLOW_CTX_DAG_EMAIL=estudiante@uniandes.edu.co
AIRFLOW_CTX_DAG_OWNER=Estudiante
AIRFLOW_CTX_DAG_ID=ETL
AIRFLOW_CTX_TASK_ID=poblar_tablas.poblar_date
AIRFLOW_CTX_EXECUTION_DATE=2022-05-05T15:19:55.441542+00:00
AIRFLOW_CTX_DAG_RUN_ID=manual__2022-05-05T15:19:55.441542+00:00
[2022-05-19 02:00:43,589] {base.py:79} INFO - Using connection to: id: postgres_localhost. Host: host.docker.internal, Port: 5432, Schema: WWWIDWGrupo16, Login: Grupo16BI, Password: ***, extra: {}
[2022-05-19 02:00:44,428] {taskinstance.py:1774} ERROR - Task failed with exception
Traceback (most recent call last):
  File "/home/airflow/.local/lib/python3.7/site-packages/airflow/providers/postgres/operators/postgres.py", line 92, in execute
    self.hook.run(self.sql, self.autocommit, parameters=self.parameters)
  File "/home/airflow/.local/lib/python3.7/site-packages/airflow/hooks/dbapi.py", line 198, in run
    with closing(self.get_conn()) as conn:
  File "/home/airflow/.local/lib/python3.7/site-packages/airflow/providers/postgres/hooks/postgres.py", line 113, in get_conn
    self.conn = psycopg2.connect(**conn_args)
  File "/home/airflow/.local/lib/python3.7/site-packages/psycopg2/__init__.py", line 122, in connect
    conn = _connect(dsn, connection_factory=connection_factory, **kwasync)
psycopg2.OperationalError
[2022-05-19 02:00:44,599] {taskinstance.py:1288} INFO - Marking task as FAILED. dag_id=ETL, task_id=poblar_tablas.poblar_date, execution_date=20220505T151955, start_date=20220519T020040, end_date=20220519T020044
[2022-05-19 02:00:44,994] {standard_task_runner.py:98} ERROR - Failed to execute job 24 for task poblar_tablas.poblar_date (; 3099)
[2022-05-19 02:00:45,093] {local_task_job.py:154} INFO - Task exited with return code 1
[2022-05-19 02:00:45,334] {local_task_job.py:264} INFO - 0 downstream tasks scheduled from follow-on schedule check
