[2022-05-19 02:00:53,148] {taskinstance.py:1043} INFO - Dependencies all met for <TaskInstance: ETL.poblar_tablas.poblar_date scheduled__2022-05-18T00:00:00+00:00 [queued]>
[2022-05-19 02:00:53,170] {taskinstance.py:1043} INFO - Dependencies all met for <TaskInstance: ETL.poblar_tablas.poblar_date scheduled__2022-05-18T00:00:00+00:00 [queued]>
[2022-05-19 02:00:53,171] {taskinstance.py:1249} INFO - 
--------------------------------------------------------------------------------
[2022-05-19 02:00:53,173] {taskinstance.py:1250} INFO - Starting attempt 1 of 1
[2022-05-19 02:00:53,173] {taskinstance.py:1251} INFO - 
--------------------------------------------------------------------------------
[2022-05-19 02:00:53,192] {taskinstance.py:1270} INFO - Executing <Task(PostgresOperator): poblar_tablas.poblar_date> on 2022-05-18 00:00:00+00:00
[2022-05-19 02:00:53,202] {standard_task_runner.py:52} INFO - Started process 3108 to run task
[2022-05-19 02:00:53,207] {standard_task_runner.py:79} INFO - Running: ['***', 'tasks', 'run', 'ETL', 'poblar_tablas.poblar_date', 'scheduled__2022-05-18T00:00:00+00:00', '--job-id', '31', '--raw', '--subdir', 'DAGS_FOLDER/ELT.py', '--cfg-path', '/tmp/tmp2a0_a3xv', '--error-file', '/tmp/tmpk9gwpn0a']
[2022-05-19 02:00:53,208] {standard_task_runner.py:80} INFO - Job 31: Subtask poblar_tablas.poblar_date
[2022-05-19 02:00:53,313] {logging_mixin.py:109} INFO - Running <TaskInstance: ETL.poblar_tablas.poblar_date scheduled__2022-05-18T00:00:00+00:00 [running]> on host 096c3bc3ad3a
[2022-05-19 02:00:53,547] {taskinstance.py:1448} INFO - Exporting the following env vars:
AIRFLOW_CTX_DAG_EMAIL=estudiante@uniandes.edu.co
AIRFLOW_CTX_DAG_OWNER=Estudiante
AIRFLOW_CTX_DAG_ID=ETL
AIRFLOW_CTX_TASK_ID=poblar_tablas.poblar_date
AIRFLOW_CTX_EXECUTION_DATE=2022-05-18T00:00:00+00:00
AIRFLOW_CTX_DAG_RUN_ID=scheduled__2022-05-18T00:00:00+00:00
[2022-05-19 02:00:53,570] {base.py:79} INFO - Using connection to: id: postgres_localhost. Host: host.docker.internal, Port: 5432, Schema: WWWIDWGrupo16, Login: Grupo16BI, Password: ***, extra: {}
[2022-05-19 02:00:54,120] {taskinstance.py:1774} ERROR - Task failed with exception
Traceback (most recent call last):
  File "/home/airflow/.local/lib/python3.7/site-packages/airflow/providers/postgres/operators/postgres.py", line 92, in execute
    self.hook.run(self.sql, self.autocommit, parameters=self.parameters)
  File "/home/airflow/.local/lib/python3.7/site-packages/airflow/hooks/dbapi.py", line 198, in run
    with closing(self.get_conn()) as conn:
  File "/home/airflow/.local/lib/python3.7/site-packages/airflow/providers/postgres/hooks/postgres.py", line 113, in get_conn
    self.conn = psycopg2.connect(**conn_args)
  File "/home/airflow/.local/lib/python3.7/site-packages/psycopg2/__init__.py", line 122, in connect
    conn = _connect(dsn, connection_factory=connection_factory, **kwasync)
psycopg2.OperationalError
[2022-05-19 02:00:54,189] {taskinstance.py:1288} INFO - Marking task as FAILED. dag_id=ETL, task_id=poblar_tablas.poblar_date, execution_date=20220518T000000, start_date=20220519T020053, end_date=20220519T020054
[2022-05-19 02:00:54,209] {standard_task_runner.py:98} ERROR - Failed to execute job 31 for task poblar_tablas.poblar_date (; 3108)
[2022-05-19 02:00:54,258] {local_task_job.py:154} INFO - Task exited with return code 1
[2022-05-19 02:00:54,313] {local_task_job.py:264} INFO - 0 downstream tasks scheduled from follow-on schedule check
