[2022-05-19 02:01:53,369] {taskinstance.py:1043} INFO - Dependencies all met for <TaskInstance: ETL.crear_tablas_en_postgres manual__2022-05-19T02:01:43.581309+00:00 [queued]>
[2022-05-19 02:01:53,387] {taskinstance.py:1043} INFO - Dependencies all met for <TaskInstance: ETL.crear_tablas_en_postgres manual__2022-05-19T02:01:43.581309+00:00 [queued]>
[2022-05-19 02:01:53,388] {taskinstance.py:1249} INFO - 
--------------------------------------------------------------------------------
[2022-05-19 02:01:53,402] {taskinstance.py:1250} INFO - Starting attempt 1 of 1
[2022-05-19 02:01:53,434] {taskinstance.py:1251} INFO - 
--------------------------------------------------------------------------------
[2022-05-19 02:01:53,556] {taskinstance.py:1270} INFO - Executing <Task(PostgresOperator): crear_tablas_en_postgres> on 2022-05-19 02:01:43.581309+00:00
[2022-05-19 02:01:53,644] {standard_task_runner.py:52} INFO - Started process 3163 to run task
[2022-05-19 02:01:53,704] {standard_task_runner.py:79} INFO - Running: ['***', 'tasks', 'run', 'ETL', 'crear_tablas_en_postgres', 'manual__2022-05-19T02:01:43.581309+00:00', '--job-id', '32', '--raw', '--subdir', 'DAGS_FOLDER/ELT.py', '--cfg-path', '/tmp/tmpwwaaha5b', '--error-file', '/tmp/tmpbg81xfc8']
[2022-05-19 02:01:53,721] {standard_task_runner.py:80} INFO - Job 32: Subtask crear_tablas_en_postgres
[2022-05-19 02:01:54,123] {logging_mixin.py:109} INFO - Running <TaskInstance: ETL.crear_tablas_en_postgres manual__2022-05-19T02:01:43.581309+00:00 [running]> on host 096c3bc3ad3a
[2022-05-19 02:01:54,395] {taskinstance.py:1448} INFO - Exporting the following env vars:
AIRFLOW_CTX_DAG_EMAIL=estudiante@uniandes.edu.co
AIRFLOW_CTX_DAG_OWNER=Estudiante
AIRFLOW_CTX_DAG_ID=ETL
AIRFLOW_CTX_TASK_ID=crear_tablas_en_postgres
AIRFLOW_CTX_EXECUTION_DATE=2022-05-19T02:01:43.581309+00:00
AIRFLOW_CTX_DAG_RUN_ID=manual__2022-05-19T02:01:43.581309+00:00
[2022-05-19 02:01:54,516] {base.py:79} INFO - Using connection to: id: postgres_localhost. Host: host.docker.internal, Port: 5432, Schema: WWWIDWGrupo16, Login: Grupo16BI, Password: ***, extra: {}
[2022-05-19 02:01:55,355] {taskinstance.py:1774} ERROR - Task failed with exception
Traceback (most recent call last):
  File "/home/airflow/.local/lib/python3.7/site-packages/airflow/providers/postgres/operators/postgres.py", line 92, in execute
    self.hook.run(self.sql, self.autocommit, parameters=self.parameters)
  File "/home/airflow/.local/lib/python3.7/site-packages/airflow/hooks/dbapi.py", line 198, in run
    with closing(self.get_conn()) as conn:
  File "/home/airflow/.local/lib/python3.7/site-packages/airflow/providers/postgres/hooks/postgres.py", line 113, in get_conn
    self.conn = psycopg2.connect(**conn_args)
  File "/home/airflow/.local/lib/python3.7/site-packages/psycopg2/__init__.py", line 122, in connect
    conn = _connect(dsn, connection_factory=connection_factory, **kwasync)
psycopg2.OperationalError
[2022-05-19 02:01:55,419] {taskinstance.py:1288} INFO - Marking task as FAILED. dag_id=ETL, task_id=crear_tablas_en_postgres, execution_date=20220519T020143, start_date=20220519T020153, end_date=20220519T020155
[2022-05-19 02:01:55,465] {standard_task_runner.py:98} ERROR - Failed to execute job 32 for task crear_tablas_en_postgres (; 3163)
[2022-05-19 02:01:55,541] {local_task_job.py:154} INFO - Task exited with return code 1
[2022-05-19 02:01:55,729] {local_task_job.py:264} INFO - 0 downstream tasks scheduled from follow-on schedule check
